Workbook
Name Sale_Table: Table1[]
Name Slicer_Month: #N/A
Name Slicer_Payment_Method: #N/A
Name Slicer_States: #N/A

Sheet 01.Table
A1: Transaction ID | B1: Date | C1: Customer name | D1: Product | E1: Payment Method | F1: Unit Sold | G1: Buying Price | H1: Selling Price | I1: Total Buying | J1: Total Sales | K1: Profit | L1: States | M1: City | N1: Month
A2: T258 | B2: 45293 | C2: Rahul | D2: Headphones | E2: Cash | F2: 10 | G2: 6131.7 | H2: 7570 | I2: =F2*G2 -> 61317 | J2: 75700 | K2: =J2-I2 -> 14383 | L2: Uttar Pradesh | M2: Lucknow | N2: =TEXT(Table1[[#This Row],[Date]],"mmm") -> Jan
A3: T240 | B3: 45294 | C3: Rahul | D3: Headphones | E3: Cash | F3: 4 | G3: 42856.45 | H3: 47095 | I3: =F3*G3 -> 171425.8 | J3: 188380 | K3: =J3-I3 -> 16954.2 | L3: Uttar Pradesh | M3: Agra | N3: =TEXT(Table1[[#This Row],[Date]],"mmm") -> Jan
A4: T048 | B4: 45296 | C4: Karan | D4: Headphones | E4: Cash | F4: 2 | G4: 3289.29 | H4: 3963 | I4: ='01.Table'!$G4*'01.Table'!$F4 -> 6578.58 | J4: 7926 | K4: ='01.Table'!$J4-'01.Table'!$I4 -> 1347.42 | L4: Tamil Nadu | M4: Trichy | N4: =TEXT(Table1[[#This Row],[Date]],"mmm") -> Jan
A5: T202 | B5: 45296 | C5: Rahul | D5: Headphones | E5: Cash | F5: 6 | G5: 34115.31 | H5: 39213 | I5: =F5*G5 -> 204691.86 | J5: 235278 | K5: =J5-I5 -> 30586.14 | L5: Karnataka | M5: Davanagere | N5: =TEXT(Table1[[#This Row],[Date]],"mmm") -> Jan
A6: T228 | B6: 45298 | C6: Vikram | D6: Keyboard | E6: Cash | F6: 3 | G6: 12962.04 | H6: 15431 | I6: =F6*G6 -> 38886.12 | J6: 46293 | K6: =J6-I6 -> 7406.88 | L6: Karnataka | M6: Bengaluru | N6: =TEXT(Table1[[#This Row],[Date]],"mmm") -> Jan
A7: T016 | B7: 45301 | C7: Priya | D7: Tablet | E7: Online | F7: 2 | G7: 17407.26 | H7: 20241 | I7: ='01.Table'!$G36*'01.Table'!$F36 -> 20135.92 | J7: 40482 | K7: ='01.Table'!$J36-'01.Table'!$I36 -> 4420.08 | L7: Tamil Nadu | M7: Tirunelveli | N7: =TEXT(Table1[[#This Row],[Date]],"mmm") -> Jan
A8: T107 | B8: 45304 | C8: Rahul | D8: Monitor | E8: Cash | F8: 3 | G8: 26482.14 | H8: 32694 | I8: =F8*G8 -> 79446.42 | J8: 98082 | K8: =J8-I8 -> 18635.58 | L8: Gujarat | M8: Vadodara | N8: =TEXT(Table1[[#This Row],[Date]],"mmm") -> Jan
A9: T111 | B9: 45304 | C9: Shivam | D9: Monitor | E9: Cash | F9: 10 | G9: 19596.75 | H9: 22525 | I9: =F9*G9 -> 195967.5 | J9: 225250 | K9: =J9-I9 -> 29282.5 | L9: Karnataka | M9: Bengaluru | N9: =TEXT(Table1[[#This Row],[Date]],"mmm") -> Jan
A10: T134 | B10: 45304 | C10: Sneha | D10: Mouse | E10: Online | F10: 9 | G10: 19864.8 | H10: 24831 | I10: =F10*G10 -> 178783.2 | J10: 223479 | K10: =J10-I10 -> 44695.8 | L10: Tamil Nadu | M10: Tirunelveli | N10: =TEXT(Table1[[#This Row],[Date]],"mmm") -> Jan
A11: T136 | B11: 45304 | C11: Neha | D11: Keyboard | E11: Online | F11: 2 | G11: 36479.34 | H11: 44487 | I11: =F11*G11 -> 72958.68 | J11: 88974 | K11: =J11-I11 -> 16015.32 | L11: Karnataka | M11: Hubballi | N11: =TEXT(Table1[[#This Row],[Date]],"mmm") -> Jan
A12: T050 | B12: 45305 | C12: Neha | D12: Headphones | E12: Cash | F12: 10 | G12: 25648.8 | H12: 32061 | I12: ='01.Table'!$G6*'01.Table'!$F6 -> 38886.12 | J12: 320610 | K12: ='01.Table'!$J6-'01.Table'!$I6 -> 7406.88 | L12: Tamil Nadu | M12: Madurai | N12: =TEXT(Table1[[#This Row],[Date]],"mmm") -> Jan
A13: T026 | B13: 45306 | C13: Rahul | D13: Mouse | E13: Cash | F13: 5 | G13: 6872.42 | H13: 8381 | I13: ='01.Table'!$G23*'01.Table'!$F23 -> 216172 | J13: 41905 | K13: ='01.Table'!$J23-'01.Table'!$I23 -> 29478 | L13: Karnataka | M13: Mangaluru | N13: =TEXT(Table1[[#This Row],[Date]],"mmm") -> Jan
A14: T198 | B14: 45306 | C14: Sneha Gupta | D14: Monitor | E14: Cash | F14: 9 | G14: 7996 | H14: 9995 | I14: =F14*G14 -> 71964 | J14: 89955 | K14: =J14-I14 -> 17991 | L14: Gujarat | M14: Vadodara | N14: =TEXT(Table1[[#This Row],[Date]],"mmm") -> Jan
A15: T218 | B15: 45306 | C15: Karan | D15: Printer | E15: Cash | F15: 9 | G15: 25294.32 | H15: 29412 | I15: =F15*G15 -> 227648.88 | J15: 264708 | K15: =J15-I15 -> 37059.12 | L15: Maharashtra | M15: Nagpur | N15: =TEXT(Table1[[#This Row],[Date]],"mmm") -> Jan
A16: T269 | B16: 45307 | C16: Neha | D16: Mouse | E16: Online | F16: 5 | G16: 16778.96 | H16: 18238 | I16: =F16*G16 -> 83894.8 | J16: 91190 | K16: =J16-I16 -> 7295.2 | L16: Delhi | M16: Dwarka | N16: =TEXT(Table1[[#This Row],[Date]],"mmm") -> Jan
A17: T021 | B17: 45310 | C17: Shivam | D17: Printer | E17: Cash | F17: 5 | G17: 19801.36 | H17: 24148 | I17: ='01.Table'!$G28*'01.Table'!$F28 -> 38341.92 | J17: 120740 | K17: ='01.Table'!$J28-'01.Table'!$I28 -> 3334.08 | L17: Delhi | M17: New Delhi | N17: =TEXT(Table1[[#This Row],[Date]],"mmm") -> Jan
A18: T279 | B18: 45310 | C18: Anita | D18: Tablet | E18: Online | F18: 5 | G18: 32226.01 | H18: 36209 | I18: =F18*G18 -> 161130.05 | J18: 181045 | K18: =J18-I18 -> 19914.95 | L18: Delhi | M18: Karol Bagh | N18: =TEXT(Table1[[#This Row],[Date]],"mmm") -> Jan
A19: T252 | B19: 45313 | C19: Karan | D19: Monitor | E19: Cash | F19: 3 | G19: 22194.82 | H19: 24938 | I19: =F19*G19 -> 66584.46 | J19: 74814 | K19: =J19-I19 -> 8229.54 | L19: Uttar Pradesh | M19: Varanasi | N19: =TEXT(Table1[[#This Row],[Date]],"mmm") -> Jan
A20: T292 | B20: 45313 | C20: Shivam | D20: Headphones | E20: Online | F20: 5 | G20: 31449.6 | H20: 34560 | I20: =F20*G20 -> 157248 | J20: 172800 | K20: =J20-I20 -> 15552 | L20: Tamil Nadu | M20: Tirunelveli | N20: =TEXT(Table1[[#This Row],[Date]],"mmm") -> Jan
A21: T034 | B21: 45314 | C21: Sneha | D21: Monitor | E21: Cash | F21: 2 | G21: 15959.28 | H21: 18344 | I21: ='01.Table'!$G19*'01.Table'!$F19 -> 66584.46 | J21: 36688 | K21: ='01.Table'!$J19-'01.Table'!$I19 -> 8229.54 | L21: Karnataka | M21: Bengaluru | N21: =TEXT(Table1[[#This Row],[Date]],"mmm") -> Jan
A22: T226 | B22: 45318 | C22: Neha | D22: Headphones | E22: Online | F22: 6 | G22: 44541.9 | H22: 49491 | I22: =F22*G22 -> 267251.4 | J22: 296946 | K22: =J22-I22 -> 29694.6 | L22: Maharashtra | M22: Aurangabad | N22: =TEXT(Table1[[#This Row],[Date]],"mmm") -> Jan
A23: T290 | B23: 45319 | C23: Karan | D23: Printer | E23: Online | F23: 10 | G23: 21617.2 | H23: 24565 | I23: =F23*G23 -> 216172 | J23: 245650 | K23: =J23-I23 -> 29478 | L23: Tamil Nadu | M23: Madurai | N23: =TEXT(Table1[[#This Row],[Date]],"mmm") -> Jan
A24: T047 | B24: 45322 | C24: Sneha | D24: Headphones | E24: Cash | F24: 10 | G24: 7005.7 | H24: 8242 | I24: ='01.Table'!$G3*'01.Table'!$F3 -> 171425.8 | J24: 82420 | K24: ='01.Table'!$J3-'01.Table'!$I3 -> 16954.2 | L24: Tamil Nadu | M24: Chennai | N24: =TEXT(Table1[[#This Row],[Date]],"mmm") -> Jan
A25: T040 | B25: 45323 | C25: Shivam | D25: Laptop | E25: Online | F25: 4 | G25: 16722.26 | H25: 20393 | I25: ='01.Table'!$G15*'01.Table'!$F15 -> 227648.88 | J25: 81572 | K25: ='01.Table'!$J15-'01.Table'!$I15 -> 37059.12 | L25: Uttar Pradesh | M25: Noida | N25: =TEXT(Table1[[#This Row],[Date]],"mmm") -> Feb
A26: T073 | B26: 45325 | C26: Rahul | D26: Mouse | E26: Online | F26: 8 | G26: 24731.32 | H26: 27788 | I26: =F26*G26 -> 197850.56 | J26: 222304 | K26: =J26-I26 -> 24453.44 | L26: Tamil Nadu | M26: Coimbatore | N26: =TEXT(Table1[[#This Row],[Date]],"mmm") -> Feb
A27: T185 | B27: 45325 | C27: Neha | D27: Monitor | E27: Cash | F27: 10 | G27: 10941.6 | H27: 13677 | I27: =F27*G27 -> 109416 | J27: 136770 | K27: =J27-I27 -> 27354 | L27: Tamil Nadu | M27: Salem | N27: =TEXT(Table1[[#This Row],[Date]],"mmm") -> Feb
A28: T179 | B28: 45326 | C28: Rahul | D28: Tablet | E28: Online | F28: 2 | G28: 19170.96 | H28: 20838 | I28: =F28*G28 -> 38341.92 | J28: 41676 | K28: =J28-I28 -> 3334.08 | L28: Maharashtra | M28: Aurangabad | N28: =TEXT(Table1[[#This Row],[Date]],"mmm") -> Feb
A29: T186 | B29: 45330 | C29: Vikram | D29: Mouse | E29: Cash | F29: 6 | G29: 3752.73 | H29: 4633 | I29: =F29*G29 -> 22516.38 | J29: 27798 | K29: =J29-I29 -> 5281.62 | L29: Delhi | M29: Karol Bagh | N29: =TEXT(Table1[[#This Row],[Date]],"mmm") -> Feb
A30: T004 | B30: 45331 | C30: Rahul | D30: Webcam | E30: Cash | F30: 5 | G30: 8220.04 | H30: 9236 | I30: ='01.Table'!$G44*'01.Table'!$F44 -> 51111 | J30: 46180 | K30: ='01.Table'!$J44-'01.Table'!$I44 -> 5679 | L30: Uttar Pradesh | M30: Lucknow | N30: =TEXT(Table1[[#This Row],[Date]],"mmm") -> Feb
A31: T151 | B31: 45332 | C31: Priya Gupta | D31: Laptop | E31: Online | F31: 2 | G31: 22920.48 | H31: 26046 | I31: =F31*G31 -> 45840.96 | J31: 52092 | K31: =J31-I31 -> 6251.04 | L31: Karnataka | M31: Davanagere | N31: =TEXT(Table1[[#This Row],[Date]],"mmm") -> Feb
A32: T099 | B32: 45333 | C32: Priya | D32: Mouse | E32: Online | F32: 7 | G32: 44021.7 | H32: 48913 | I32: =F32*G32 -> 308151.9 | J32: 342391 | K32: =J32-I32 -> 34239.1 | L32: Uttar Pradesh | M32: Ghaziabad | N32: =TEXT(Table1[[#This Row],[Date]],"mmm") -> Feb
A33: T270 | B33: 45333 | C33: Rahul | D33: Printer | E33: Cash | F33: 4 | G33: 36675 | H33: 40750 | I33: =F33*G33 -> 146700 | J33: 163000 | K33: =J33-I33 -> 16300 | L33: Uttar Pradesh | M33: Kanpur | N33: =TEXT(Table1[[#This Row],[Date]],"mmm") -> Feb
A34: T075 | B34: 45334 | C34: Sneha Gupta | D34: Mouse | E34: Online | F34: 8 | G34: 23217.12 | H34: 25236 | I34: =F34*G34 -> 185736.96 | J34: 201888 | K34: =J34-I34 -> 16151.04 | L34: Uttar Pradesh | M34: Ghaziabad | N34: =TEXT(Table1[[#This Row],[Date]],"mmm") -> Feb
A35: T217 | B35: 45337 | C35: Neha | D35: Monitor | E35: Online | F35: 4 | G35: 5816.7 | H35: 6463 | I35: =F35*G35 -> 23266.8 | J35: 25852 | K35: =J35-I35 -> 2585.2 | L35: Tamil Nadu | M35: Coimbatore | N35: =TEXT(Table1[[#This Row],[Date]],"mmm") -> Feb
A36: T203 | B36: 45338 | C36: Sneha Gupta | D36: Mouse | E36: Cash | F36: 7 | G36: 2876.56 | H36: 3508 | I36: =F36*G36 -> 20135.92 | J36: 24556 | K36: =J36-I36 -> 4420.08 | L36: Uttar Pradesh | M36: Kanpur | N36: =TEXT(Table1[[#This Row],[Date]],"mmm") -> Feb
A37: T093 | B37: 45342 | C37: Pooja | D37: Monitor | E37: Cash | F37: 5 | G37: 32358.65 | H37: 38069 | I37: =F37*G37 -> 161793.25 | J37: 190345 | K37: =J37-I37 -> 28551.75 | L37: Delhi | M37: New Delhi | N37: =TEXT(Table1[[#This Row],[Date]],"mmm") -> Feb
A38: T140 | B38: 45342 | C38: Shivam | D38: Laptop | E38: Cash | F38: 2 | G38: 32589 | H38: 36210 | I38: =F38*G38 -> 65178 | J38: 72420 | K38: =J38-I38 -> 7242 | L38: Tamil Nadu | M38: Trichy | N38: =TEXT(Table1[[#This Row],[Date]],"mmm") -> Feb
A39: T020 | B39: 45343 | C39: Rahul | D39: Tablet | E39: Online | F39: 3 | G39: 23503.5 | H39: 26115 | I39: ='01.Table'!$G40*'01.Table'!$F40 -> 53041.98 | J39: 78345 | K39: ='01.Table'!$J40-'01.Table'!$I40 -> 10864.02 | L39: Uttar Pradesh | M39: Varanasi | N39: =TEXT(Table1[[#This Row],[Date]],"mmm") -> Feb
A40: T077 | B40: 45344 | C40: Anita | D40: Laptop | E40: Cash | F40: 2 | G40: 26520.99 | H40: 31953 | I40: =F40*G40 -> 53041.98 | J40: 63906 | K40: =J40-I40 -> 10864.02 | L40: Uttar Pradesh | M40: Noida | N40: =TEXT(Table1[[#This Row],[Date]],"mmm") -> Feb
...

Sheet 02.MIS Report Table
A1: =IF(ISEVEN('07.DRW'!K4),"Total Sales","Total Profit") -> Total Profit
A5: Customer name/Product | B5: Online | J5: Cash | R5: Total
B6: Headphones | C6: Keyboard | D6: Laptop | E6: Monitor | F6: Mouse | G6: Printer | H6: Tablet | I6: Webcam | J6: Headphones | K6: Keyboard | L6: Laptop | M6: Monitor | N6: Mouse | O6: Printer | P6: Tablet | Q6: Webcam
A7: Neha | B7: =SUMIFS(IF(ISEVEN('07.DRW'!$K$4),INDEX(Table1[],,10),INDEX(Table1[],,11)), Table1[[Customer name]:[Customer name]], '02.MIS Report Table'!$A7, Table1[[Payment Method]:[Payment Method]], "Online", Table1[[Product]:[Product]], '02.MIS Report Table'!B$6) -> 60772.6 | C7: =SUMIFS(IF(ISEVEN('07.DRW'!$K$4),INDEX(Table1[],,10),INDEX(Table1[],,11)), Table1[[Customer name]:[Customer name]], '02.MIS Report Table'!$A7, Table1[[Payment Method]:[Payment Method]], "Online", Table1[[Product]:[Product]], '02.MIS Report Table'!C$6) -> 16015.32 | D7: =SUMIFS(IF(ISEVEN('07.DRW'!$K$4),INDEX(Table1[],,10),INDEX(Table1[],,11)), Table1[[Customer name]:[Customer name]], '02.MIS Report Table'!$A7, Table1[[Payment Method]:[Payment Method]], "Online", Table1[[Product]:[Product]], '02.MIS Report Table'!D$6) -> 0 | E7: =SUMIFS(IF(ISEVEN('07.DRW'!$K$4),INDEX(Table1[],,10),INDEX(Table1[],,11)), Table1[[Customer name]:[Customer name]], '02.MIS Report Table'!$A7, Table1[[Payment Method]:[Payment Method]], "Online", Table1[[Product]:[Product]], '02.MIS Report Table'!E$6) -> 11079.4 | F7: =SUMIFS(IF(ISEVEN('07.DRW'!$K$4),INDEX(Table1[],,10),INDEX(Table1[],,11)), Table1[[Customer name]:[Customer name]], '02.MIS Report Table'!$A7, Table1[[Payment Method]:[Payment Method]], "Online", Table1[[Product]:[Product]], '02.MIS Report Table'!F$6) -> 48256.97 | G7: =SUMIFS(IF(ISEVEN('07.DRW'!$K$4),INDEX(Table1[],,10),INDEX(Table1[],,11)), Table1[[Customer name]:[Customer name]], '02.MIS Report Table'!$A7, Table1[[Payment Method]:[Payment Method]], "Online", Table1[[Product]:[Product]], '02.MIS Report Table'!G$6) -> 13164.48 | H7: =SUMIFS(IF(ISEVEN('07.DRW'!$K$4),INDEX(Table1[],,10),INDEX(Table1[],,11)), Table1[[Customer name]:[Customer name]], '02.MIS Report Table'!$A7, Table1[[Payment Method]:[Payment Method]], "Online", Table1[[Product]:[Product]], '02.MIS Report Table'!H$6) -> 9647.28 | I7: =SUMIFS(IF(ISEVEN('07.DRW'!$K$4),INDEX(Table1[],,10),INDEX(Table1[],,11)), Table1[[Customer name]:[Customer name]], '02.MIS Report Table'!$A7, Table1[[Payment Method]:[Payment Method]], "Online", Table1[[Product]:[Product]], '02.MIS Report Table'!I$6) -> 9212 | J7: =SUMIFS(IF(ISEVEN('07.DRW'!$K$4),INDEX(Table1[],,10),INDEX(Table1[],,11)), Table1[[Customer name]:[Customer name]], '02.MIS Report Table'!$A7, Table1[[Payment Method]:[Payment Method]], "Cash", Table1[[Product]:[Product]], '02.MIS Report Table'!B$6) -> 18021.12 | K7: =SUMIFS(IF(ISEVEN('07.DRW'!$K$4),INDEX(Table1[],,10),INDEX(Table1[],,11)), Table1[[Customer name]:[Customer name]], '02.MIS Report Table'!$A7, Table1[[Payment Method]:[Payment Method]], "Cash", Table1[[Product]:[Product]], '02.MIS Report Table'!C$6) -> 0 | L7: =SUMIFS(IF(ISEVEN('07.DRW'!$K$4),INDEX(Table1[],,10),INDEX(Table1[],,11)), Table1[[Customer name]:[Customer name]], '02.MIS Report Table'!$A7, Table1[[Payment Method]:[Payment Method]], "Cash", Table1[[Product]:[Product]], '02.MIS Report Table'!D$6) -> 0 | M7: =SUMIFS(IF(ISEVEN('07.DRW'!$K$4),INDEX(Table1[],,10),INDEX(Table1[],,11)), Table1[[Customer name]:[Customer name]], '02.MIS Report Table'!$A7, Table1[[Payment Method]:[Payment Method]], "Cash", Table1[[Product]:[Product]], '02.MIS Report Table'!E$6) -> 35759.6 | N7: =SUMIFS(IF(ISEVEN('07.DRW'!$K$4),INDEX(Table1[],,10),INDEX(Table1[],,11)), Table1[[Customer name]:[Customer name]], '02.MIS Report Table'!$A7, Table1[[Payment Method]:[Payment Method]], "Cash", Table1[[Product]:[Product]], '02.MIS Report Table'!F$6) -> 39405.6 | O7: =SUMIFS(IF(ISEVEN('07.DRW'!$K$4),INDEX(Table1[],,10),INDEX(Table1[],,11)), Table1[[Customer name]:[Customer name]], '02.MIS Report Table'!$A7, Table1[[Payment Method]:[Payment Method]], "Cash", Table1[[Product]:[Product]], '02.MIS Report Table'!G$6) -> 108580 | P7: =SUMIFS(IF(ISEVEN('07.DRW'!$K$4),INDEX(Table1[],,10),INDEX(Table1[],,11)), Table1[[Customer name]:[Customer name]], '02.MIS Report Table'!$A7, Table1[[Payment Method]:[Payment Method]], "Cash", Table1[[Product]:[Product]], '02.MIS Report Table'!H$6) -> 38911.35 | Q7: =SUMIFS(IF(ISEVEN('07.DRW'!$K$4),INDEX(Table1[],,10),INDEX(Table1[],,11)), Table1[[Customer name]:[Customer name]], '02.MIS Report Table'!$A7, Table1[[Payment Method]:[Payment Method]], "Cash", Table1[[Product]:[Product]], '02.MIS Report Table'!I$6) -> 21100.38 | R7: =SUM(B7:Q7) -> 429926.1
A8: Sneha | B8: =SUMIFS(IF(ISEVEN('07.DRW'!$K$4),INDEX(Table1[],,10),INDEX(Table1[],,11)), Table1[[Customer name]:[Customer name]], '02.MIS Report Table'!$A8, Table1[[Payment Method]:[Payment Method]], "Online", Table1[[Product]:[Product]], '02.MIS Report Table'!B$6) -> 6172.32 | C8: =SUMIFS(IF(ISEVEN('07.DRW'!$K$4),INDEX(Table1[],,10),INDEX(Table1[],,11)), Table1[[Customer name]:[Customer name]], '02.MIS Report Table'!$A8, Table1[[Payment Method]:[Payment Method]], "Online", Table1[[Product]:[Product]], '02.MIS Report Table'!C$6) -> 166184.34 | D8: =SUMIFS(IF(ISEVEN('07.DRW'!$K$4),INDEX(Table1[],,10),INDEX(Table1[],,11)), Table1[[Customer name]:[Customer name]], '02.MIS Report Table'!$A8, Table1[[Payment Method]:[Payment Method]], "Online", Table1[[Product]:[Product]], '02.MIS Report Table'!D$6) -> 340134.79 | E8: =SUMIFS(IF(ISEVEN('07.DRW'!$K$4),INDEX(Table1[],,10),INDEX(Table1[],,11)), Table1[[Customer name]:[Customer name]], '02.MIS Report Table'!$A8, Table1[[Payment Method]:[Payment Method]], "Online", Table1[[Product]:[Product]], '02.MIS Report Table'!E$6) -> 32738 | F8: =SUMIFS(IF(ISEVEN('07.DRW'!$K$4),INDEX(Table1[],,10),INDEX(Table1[],,11)), Table1[[Customer name]:[Customer name]], '02.MIS Report Table'!$A8, Table1[[Payment Method]:[Payment Method]], "Online", Table1[[Product]:[Product]], '02.MIS Report Table'!F$6) -> -10048.36 | G8: =SUMIFS(IF(ISEVEN('07.DRW'!$K$4),INDEX(Table1[],,10),INDEX(Table1[],,11)), Table1[[Customer name]:[Customer name]], '02.MIS Report Table'!$A8, Table1[[Payment Method]:[Payment Method]], "Online", Table1[[Product]:[Product]], '02.MIS Report Table'!G$6) -> 0 | H8: =SUMIFS(IF(ISEVEN('07.DRW'!$K$4),INDEX(Table1[],,10),INDEX(Table1[],,11)), Table1[[Customer name]:[Customer name]], '02.MIS Report Table'!$A8, Table1[[Payment Method]:[Payment Method]], "Online", Table1[[Product]:[Product]], '02.MIS Report Table'!H$6) -> 37795.8 | I8: =SUMIFS(IF(ISEVEN('07.DRW'!$K$4),INDEX(Table1[],,10),INDEX(Table1[],,11)), Table1[[Customer name]:[Customer name]], '02.MIS Report Table'!$A8, Table1[[Payment Method]:[Payment Method]], "Online", Table1[[Product]:[Product]], '02.MIS Report Table'!I$6) -> 7599.84 | J8: =SUMIFS(IF(ISEVEN('07.DRW'!$K$4),INDEX(Table1[],,10),INDEX(Table1[],,11)), Table1[[Customer name]:[Customer name]], '02.MIS Report Table'!$A8, Table1[[Payment Method]:[Payment Method]], "Cash", Table1[[Product]:[Product]], '02.MIS Report Table'!B$6) -> 66475.2 | K8: =SUMIFS(IF(ISEVEN('07.DRW'!$K$4),INDEX(Table1[],,10),INDEX(Table1[],,11)), Table1[[Customer name]:[Customer name]], '02.MIS Report Table'!$A8, Table1[[Payment Method]:[Payment Method]], "Cash", Table1[[Product]:[Product]], '02.MIS Report Table'!C$6) -> 0 | L8: =SUMIFS(IF(ISEVEN('07.DRW'!$K$4),INDEX(Table1[],,10),INDEX(Table1[],,11)), Table1[[Customer name]:[Customer name]], '02.MIS Report Table'!$A8, Table1[[Payment Method]:[Payment Method]], "Cash", Table1[[Product]:[Product]], '02.MIS Report Table'!D$6) -> 71057.36 | M8: =SUMIFS(IF(ISEVEN('07.DRW'!$K$4),INDEX(Table1[],,10),INDEX(Table1[],,11)), Table1[[Customer name]:[Customer name]], '02.MIS Report Table'!$A8, Table1[[Payment Method]:[Payment Method]], "Cash", Table1[[Product]:[Product]], '02.MIS Report Table'!E$6) -> 8229.54 | N8: =SUMIFS(IF(ISEVEN('07.DRW'!$K$4),INDEX(Table1[],,10),INDEX(Table1[],,11)), Table1[[Customer name]:[Customer name]], '02.MIS Report Table'!$A8, Table1[[Payment Method]:[Payment Method]], "Cash", Table1[[Product]:[Product]], '02.MIS Report Table'!F$6) -> 2700.36 | O8: =SUMIFS(IF(ISEVEN('07.DRW'!$K$4),INDEX(Table1[],,10),INDEX(Table1[],,11)), Table1[[Customer name]:[Customer name]], '02.MIS Report Table'!$A8, Table1[[Payment Method]:[Payment Method]], "Cash", Table1[[Product]:[Product]], '02.MIS Report Table'!G$6) -> 0 | P8: =SUMIFS(IF(ISEVEN('07.DRW'!$K$4),INDEX(Table1[],,10),INDEX(Table1[],,11)), Table1[[Customer name]:[Customer name]], '02.MIS Report Table'!$A8, Table1[[Payment Method]:[Payment Method]], "Cash", Table1[[Product]:[Product]], '02.MIS Report Table'!H$6) -> 17982.8 | Q8: =SUMIFS(IF(ISEVEN('07.DRW'!$K$4),INDEX(Table1[],,10),INDEX(Table1[],,11)), Table1[[Customer name]:[Customer name]], '02.MIS Report Table'!$A8, Table1[[Payment Method]:[Payment Method]], "Cash", Table1[[Product]:[Product]], '02.MIS Report Table'!I$6) -> 17868.88 | R8: =SUM(B8:Q8) -> 764890.87
A9: Karan | B9: =SUMIFS(IF(ISEVEN('07.DRW'!$K$4),INDEX(Table1[],,10),INDEX(Table1[],,11)), Table1[[Customer name]:[Customer name]], '02.MIS Report Table'!$A9, Table1[[Payment Method]:[Payment Method]], "Online", Table1[[Product]:[Product]], '02.MIS Report Table'!B$6) -> 56347.9 | C9: =SUMIFS(IF(ISEVEN('07.DRW'!$K$4),INDEX(Table1[],,10),INDEX(Table1[],,11)), Table1[[Customer name]:[Customer name]], '02.MIS Report Table'!$A9, Table1[[Payment Method]:[Payment Method]], "Online", Table1[[Product]:[Product]], '02.MIS Report Table'!C$6) -> 96496.34 | D9: =SUMIFS(IF(ISEVEN('07.DRW'!$K$4),INDEX(Table1[],,10),INDEX(Table1[],,11)), Table1[[Customer name]:[Customer name]], '02.MIS Report Table'!$A9, Table1[[Payment Method]:[Payment Method]], "Online", Table1[[Product]:[Product]], '02.MIS Report Table'!D$6) -> 40117.68 | E9: =SUMIFS(IF(ISEVEN('07.DRW'!$K$4),INDEX(Table1[],,10),INDEX(Table1[],,11)), Table1[[Customer name]:[Customer name]], '02.MIS Report Table'!$A9, Table1[[Payment Method]:[Payment Method]], "Online", Table1[[Product]:[Product]], '02.MIS Report Table'!E$6) -> 106081.18 | F9: =SUMIFS(IF(ISEVEN('07.DRW'!$K$4),INDEX(Table1[],,10),INDEX(Table1[],,11)), Table1[[Customer name]:[Customer name]], '02.MIS Report Table'!$A9, Table1[[Payment Method]:[Payment Method]], "Online", Table1[[Product]:[Product]], '02.MIS Report Table'!F$6) -> 0 | G9: =SUMIFS(IF(ISEVEN('07.DRW'!$K$4),INDEX(Table1[],,10),INDEX(Table1[],,11)), Table1[[Customer name]:[Customer name]], '02.MIS Report Table'!$A9, Table1[[Payment Method]:[Payment Method]], "Online", Table1[[Product]:[Product]], '02.MIS Report Table'!G$6) -> 80402.24 | H9: =SUMIFS(IF(ISEVEN('07.DRW'!$K$4),INDEX(Table1[],,10),INDEX(Table1[],,11)), Table1[[Customer name]:[Customer name]], '02.MIS Report Table'!$A9, Table1[[Payment Method]:[Payment Method]], "Online", Table1[[Product]:[Product]], '02.MIS Report Table'!H$6) -> 46538.24 | I9: =SUMIFS(IF(ISEVEN('07.DRW'!$K$4),INDEX(Table1[],,10),INDEX(Table1[],,11)), Table1[[Customer name]:[Customer name]], '02.MIS Report Table'!$A9, Table1[[Payment Method]:[Payment Method]], "Online", Table1[[Product]:[Product]], '02.MIS Report Table'!I$6) -> 14814 | J9: =SUMIFS(IF(ISEVEN('07.DRW'!$K$4),INDEX(Table1[],,10),INDEX(Table1[],,11)), Table1[[Customer name]:[Customer name]], '02.MIS Report Table'!$A9, Table1[[Payment Method]:[Payment Method]], "Cash", Table1[[Product]:[Product]], '02.MIS Report Table'!B$6) -> 6282.48 | K9: =SUMIFS(IF(ISEVEN('07.DRW'!$K$4),INDEX(Table1[],,10),INDEX(Table1[],,11)), Table1[[Customer name]:[Customer name]], '02.MIS Report Table'!$A9, Table1[[Payment Method]:[Payment Method]], "Cash", Table1[[Product]:[Product]], '02.MIS Report Table'!C$6) -> 6732.3 | L9: =SUMIFS(IF(ISEVEN('07.DRW'!$K$4),INDEX(Table1[],,10),INDEX(Table1[],,11)), Table1[[Customer name]:[Customer name]], '02.MIS Report Table'!$A9, Table1[[Payment Method]:[Payment Method]], "Cash", Table1[[Product]:[Product]], '02.MIS Report Table'!D$6) -> 3573.9 | M9: =SUMIFS(IF(ISEVEN('07.DRW'!$K$4),INDEX(Table1[],,10),INDEX(Table1[],,11)), Table1[[Customer name]:[Customer name]], '02.MIS Report Table'!$A9, Table1[[Payment Method]:[Payment Method]], "Cash", Table1[[Product]:[Product]], '02.MIS Report Table'!E$6) -> 8229.54 | N9: =SUMIFS(IF(ISEVEN('07.DRW'!$K$4),INDEX(Table1[],,10),INDEX(Table1[],,11)), Table1[[Customer name]:[Customer name]], '02.MIS Report Table'!$A9, Table1[[Payment Method]:[Payment Method]], "Cash", Table1[[Product]:[Product]], '02.MIS Report Table'!F$6) -> 84576.7 | O9: =SUMIFS(IF(ISEVEN('07.DRW'!$K$4),INDEX(Table1[],,10),INDEX(Table1[],,11)), Table1[[Customer name]:[Customer name]], '02.MIS Report Table'!$A9, Table1[[Payment Method]:[Payment Method]], "Cash", Table1[[Product]:[Product]], '02.MIS Report Table'!G$6) -> 41560.17 | P9: =SUMIFS(IF(ISEVEN('07.DRW'!$K$4),INDEX(Table1[],,10),INDEX(Table1[],,11)), Table1[[Customer name]:[Customer name]], '02.MIS Report Table'!$A9, Table1[[Payment Method]:[Payment Method]], "Cash", Table1[[Product]:[Product]], '02.MIS Report Table'!H$6) -> 11834.88 | Q9: =SUMIFS(IF(ISEVEN('07.DRW'!$K$4),INDEX(Table1[],,10),INDEX(Table1[],,11)), Table1[[Customer name]:[Customer name]], '02.MIS Report Table'!$A9, Table1[[Payment Method]:[Payment Method]], "Cash", Table1[[Product]:[Product]], '02.MIS Report Table'!I$6) -> 19574.73 | R9: =SUM(B9:Q9) -> 623162.28
A10: Anita | B10: =SUMIFS(IF(ISEVEN('07.DRW'!$K$4),INDEX(Table1[],,10),INDEX(Table1[],,11)), Table1[[Customer name]:[Customer name]], '02.MIS Report Table'!$A10, Table1[[Payment Method]:[Payment Method]], "Online", Table1[[Product]:[Product]], '02.MIS Report Table'!B$6) -> 16305.54 | C10: =SUMIFS(IF(ISEVEN('07.DRW'!$K$4),INDEX(Table1[],,10),INDEX(Table1[],,11)), Table1[[Customer name]:[Customer name]], '02.MIS Report Table'!$A10, Table1[[Payment Method]:[Payment Method]], "Online", Table1[[Product]:[Product]], '02.MIS Report Table'!C$6) -> 16015.32 | D10: =SUMIFS(IF(ISEVEN('07.DRW'!$K$4),INDEX(Table1[],,10),INDEX(Table1[],,11)), Table1[[Customer name]:[Customer name]], '02.MIS Report Table'!$A10, Table1[[Payment Method]:[Payment Method]], "Online", Table1[[Product]:[Product]], '02.MIS Report Table'!D$6) -> 45640.4 | E10: =SUMIFS(IF(ISEVEN('07.DRW'!$K$4),INDEX(Table1[],,10),INDEX(Table1[],,11)), Table1[[Customer name]:[Customer name]], '02.MIS Report Table'!$A10, Table1[[Payment Method]:[Payment Method]], "Online", Table1[[Product]:[Product]], '02.MIS Report Table'!E$6) -> 0 | F10: =SUMIFS(IF(ISEVEN('07.DRW'!$K$4),INDEX(Table1[],,10),INDEX(Table1[],,11)), Table1[[Customer name]:[Customer name]], '02.MIS Report Table'!$A10, Table1[[Payment Method]:[Payment Method]], "Online", Table1[[Product]:[Product]], '02.MIS Report Table'!F$6) -> -146076.88 | G10: =SUMIFS(IF(ISEVEN('07.DRW'!$K$4),INDEX(Table1[],,10),INDEX(Table1[],,11)), Table1[[Customer name]:[Customer name]], '02.MIS Report Table'!$A10, Table1[[Payment Method]:[Payment Method]], "Online", Table1[[Product]:[Product]], '02.MIS Report Table'!G$6) -> 4723.8 | H10: =SUMIFS(IF(ISEVEN('07.DRW'!$K$4),INDEX(Table1[],,10),INDEX(Table1[],,11)), Table1[[Customer name]:[Customer name]], '02.MIS Report Table'!$A10, Table1[[Payment Method]:[Payment Method]], "Online", Table1[[Product]:[Product]], '02.MIS Report Table'!H$6) -> 42364.99 | I10: =SUMIFS(IF(ISEVEN('07.DRW'!$K$4),INDEX(Table1[],,10),INDEX(Table1[],,11)), Table1[[Customer name]:[Customer name]], '02.MIS Report Table'!$A10, Table1[[Payment Method]:[Payment Method]], "Online", Table1[[Product]:[Product]], '02.MIS Report Table'!I$6) -> 11034.4 | J10: =SUMIFS(IF(ISEVEN('07.DRW'!$K$4),INDEX(Table1[],,10),INDEX(Table1[],,11)), Table1[[Customer name]:[Customer name]], '02.MIS Report Table'!$A10, Table1[[Payment Method]:[Payment Method]], "Cash", Table1[[Product]:[Product]], '02.MIS Report Table'!B$6) -> 56696.94 | K10: =SUMIFS(IF(ISEVEN('07.DRW'!$K$4),INDEX(Table1[],,10),INDEX(Table1[],,11)), Table1[[Customer name]:[Customer name]], '02.MIS Report Table'!$A10, Table1[[Payment Method]:[Payment Method]], "Cash", Table1[[Product]:[Product]], '02.MIS Report Table'!C$6) -> 44695.8 | L10: =SUMIFS(IF(ISEVEN('07.DRW'!$K$4),INDEX(Table1[],,10),INDEX(Table1[],,11)), Table1[[Customer name]:[Customer name]], '02.MIS Report Table'!$A10, Table1[[Payment Method]:[Payment Method]], "Cash", Table1[[Product]:[Product]], '02.MIS Report Table'!D$6) -> 10864.02 | M10: =SUMIFS(IF(ISEVEN('07.DRW'!$K$4),INDEX(Table1[],,10),INDEX(Table1[],,11)), Table1[[Customer name]:[Customer name]], '02.MIS Report Table'!$A10, Table1[[Payment Method]:[Payment Method]], "Cash", Table1[[Product]:[Product]], '02.MIS Report Table'!E$6) -> 0 | N10: =SUMIFS(IF(ISEVEN('07.DRW'!$K$4),INDEX(Table1[],,10),INDEX(Table1[],,11)), Table1[[Customer name]:[Customer name]], '02.MIS Report Table'!$A10, Table1[[Payment Method]:[Payment Method]], "Cash", Table1[[Product]:[Product]], '02.MIS Report Table'!F$6) -> 0 | O10: =SUMIFS(IF(ISEVEN('07.DRW'!$K$4),INDEX(Table1[],,10),INDEX(Table1[],,11)), Table1[[Customer name]:[Customer name]], '02.MIS Report Table'!$A10, Table1[[Payment Method]:[Payment Method]], "Cash", Table1[[Product]:[Product]], '02.MIS Report Table'!G$6) -> 54140.4 | P10: =SUMIFS(IF(ISEVEN('07.DRW'!$K$4),INDEX(Table1[],,10),INDEX(Table1[],,11)), Table1[[Customer name]:[Customer name]], '02.MIS Report Table'!$A10, Table1[[Payment Method]:[Payment Method]], "Cash", Table1[[Product]:[Product]], '02.MIS Report Table'!H$6) -> 20765.97 | Q10: =SUMIFS(IF(ISEVEN('07.DRW'!$K$4),INDEX(Table1[],,10),INDEX(Table1[],,11)), Table1[[Customer name]:[Customer name]], '02.MIS Report Table'!$A10, Table1[[Payment Method]:[Payment Method]], "Cash", Table1[[Product]:[Product]], '02.MIS Report Table'!I$6) -> 79311.17 | R10: =SUM(B10:Q10) -> 256481.87
A11: Vikram | B11: =SUMIFS(IF(ISEVEN('07.DRW'!$K$4),INDEX(Table1[],,10),INDEX(Table1[],,11)), Table1[[Customer name]:[Customer name]], '02.MIS Report Table'!$A11, Table1[[Payment Method]:[Payment Method]], "Online", Table1[[Product]:[Product]], '02.MIS Report Table'!B$6) -> 1358.4 | C11: =SUMIFS(IF(ISEVEN('07.DRW'!$K$4),INDEX(Table1[],,10),INDEX(Table1[],,11)), Table1[[Customer name]:[Customer name]], '02.MIS Report Table'!$A11, Table1[[Payment Method]:[Payment Method]], "Online", Table1[[Product]:[Product]], '02.MIS Report Table'!C$6) -> 51955.56 | D11: =SUMIFS(IF(ISEVEN('07.DRW'!$K$4),INDEX(Table1[],,10),INDEX(Table1[],,11)), Table1[[Customer name]:[Customer name]], '02.MIS Report Table'!$A11, Table1[[Payment Method]:[Payment Method]], "Online", Table1[[Product]:[Product]], '02.MIS Report Table'!D$6) -> 12784.2 | E11: =SUMIFS(IF(ISEVEN('07.DRW'!$K$4),INDEX(Table1[],,10),INDEX(Table1[],,11)), Table1[[Customer name]:[Customer name]], '02.MIS Report Table'!$A11, Table1[[Payment Method]:[Payment Method]], "Online", Table1[[Product]:[Product]], '02.MIS Report Table'!E$6) -> 23104.38 | F11: =SUMIFS(IF(ISEVEN('07.DRW'!$K$4),INDEX(Table1[],,10),INDEX(Table1[],,11)), Table1[[Customer name]:[Customer name]], '02.MIS Report Table'!$A11, Table1[[Payment Method]:[Payment Method]], "Online", Table1[[Product]:[Product]], '02.MIS Report Table'!F$6) -> 0 | G11: =SUMIFS(IF(ISEVEN('07.DRW'!$K$4),INDEX(Table1[],,10),INDEX(Table1[],,11)), Table1[[Customer name]:[Customer name]], '02.MIS Report Table'!$A11, Table1[[Payment Method]:[Payment Method]], "Online", Table1[[Product]:[Product]], '02.MIS Report Table'!G$6) -> 10406.14 | H11: =SUMIFS(IF(ISEVEN('07.DRW'!$K$4),INDEX(Table1[],,10),INDEX(Table1[],,11)), Table1[[Customer name]:[Customer name]], '02.MIS Report Table'!$A11, Table1[[Payment Method]:[Payment Method]], "Online", Table1[[Product]:[Product]], '02.MIS Report Table'!H$6) -> 0 | I11: =SUMIFS(IF(ISEVEN('07.DRW'!$K$4),INDEX(Table1[],,10),INDEX(Table1[],,11)), Table1[[Customer name]:[Customer name]], '02.MIS Report Table'!$A11, Table1[[Payment Method]:[Payment Method]], "Online", Table1[[Product]:[Product]], '02.MIS Report Table'!I$6) -> 24613.8 | J11: =SUMIFS(IF(ISEVEN('07.DRW'!$K$4),INDEX(Table1[],,10),INDEX(Table1[],,11)), Table1[[Customer name]:[Customer name]], '02.MIS Report Table'!$A11, Table1[[Payment Method]:[Payment Method]], "Cash", Table1[[Product]:[Product]], '02.MIS Report Table'!B$6) -> 56657.77 | K11: =SUMIFS(IF(ISEVEN('07.DRW'!$K$4),INDEX(Table1[],,10),INDEX(Table1[],,11)), Table1[[Customer name]:[Customer name]], '02.MIS Report Table'!$A11, Table1[[Payment Method]:[Payment Method]], "Cash", Table1[[Product]:[Product]], '02.MIS Report Table'!C$6) -> 59876.46 | L11: =SUMIFS(IF(ISEVEN('07.DRW'!$K$4),INDEX(Table1[],,10),INDEX(Table1[],,11)), Table1[[Customer name]:[Customer name]], '02.MIS Report Table'!$A11, Table1[[Payment Method]:[Payment Method]], "Cash", Table1[[Product]:[Product]], '02.MIS Report Table'!D$6) -> 35378.2 | M11: =SUMIFS(IF(ISEVEN('07.DRW'!$K$4),INDEX(Table1[],,10),INDEX(Table1[],,11)), Table1[[Customer name]:[Customer name]], '02.MIS Report Table'!$A11, Table1[[Payment Method]:[Payment Method]], "Cash", Table1[[Product]:[Product]], '02.MIS Report Table'!E$6) -> 63620.46 | N11: =SUMIFS(IF(ISEVEN('07.DRW'!$K$4),INDEX(Table1[],,10),INDEX(Table1[],,11)), Table1[[Customer name]:[Customer name]], '02.MIS Report Table'!$A11, Table1[[Payment Method]:[Payment Method]], "Cash", Table1[[Product]:[Product]], '02.MIS Report Table'!F$6) -> 64312.37 | O11: =SUMIFS(IF(ISEVEN('07.DRW'!$K$4),INDEX(Table1[],,10),INDEX(Table1[],,11)), Table1[[Customer name]:[Customer name]], '02.MIS Report Table'!$A11, Table1[[Payment Method]:[Payment Method]], "Cash", Table1[[Product]:[Product]], '02.MIS Report Table'!G$6) -> 0 | P11: =SUMIFS(IF(ISEVEN('07.DRW'!$K$4),INDEX(Table1[],,10),INDEX(Table1[],,11)), Table1[[Customer name]:[Customer name]], '02.MIS Report Table'!$A11, Table1[[Payment Method]:[Payment Method]], "Cash", Table1[[Product]:[Product]], '02.MIS Report Table'!H$6) -> 83827.4 | Q11: =SUMIFS(IF(ISEVEN('07.DRW'!$K$4),INDEX(Table1[],,10),INDEX(Table1[],,11)), Table1[[Customer name]:[Customer name]], '02.MIS Report Table'!$A11, Table1[[Payment Method]:[Payment Method]], "Cash", Table1[[Product]:[Product]], '02.MIS Report Table'!I$6) -> 40377.6 | R11: =SUM(B11:Q11) -> 528272.74
A12: Sneha Gupta | B12: =SUMIFS(IF(ISEVEN('07.DRW'!$K$4),INDEX(Table1[],,10),INDEX(Table1[],,11)), Table1[[Customer name]:[Customer name]], '02.MIS Report Table'!$A12, Table1[[Payment Method]:[Payment Method]], "Online", Table1[[Product]:[Product]], '02.MIS Report Table'!B$6) -> 0 | C12: =SUMIFS(IF(ISEVEN('07.DRW'!$K$4),INDEX(Table1[],,10),INDEX(Table1[],,11)), Table1[[Customer name]:[Customer name]], '02.MIS Report Table'!$A12, Table1[[Payment Method]:[Payment Method]], "Online", Table1[[Product]:[Product]], '02.MIS Report Table'!C$6) -> 0 | D12: =SUMIFS(IF(ISEVEN('07.DRW'!$K$4),INDEX(Table1[],,10),INDEX(Table1[],,11)), Table1[[Customer name]:[Customer name]], '02.MIS Report Table'!$A12, Table1[[Payment Method]:[Payment Method]], "Online", Table1[[Product]:[Product]], '02.MIS Report Table'!D$6) -> -125827.64 | E12: =SUMIFS(IF(ISEVEN('07.DRW'!$K$4),INDEX(Table1[],,10),INDEX(Table1[],,11)), Table1[[Customer name]:[Customer name]], '02.MIS Report Table'!$A12, Table1[[Payment Method]:[Payment Method]], "Online", Table1[[Product]:[Product]], '02.MIS Report Table'!E$6) -> 14070.56 | F12: =SUMIFS(IF(ISEVEN('07.DRW'!$K$4),INDEX(Table1[],,10),INDEX(Table1[],,11)), Table1[[Customer name]:[Customer name]], '02.MIS Report Table'!$A12, Table1[[Payment Method]:[Payment Method]], "Online", Table1[[Product]:[Product]], '02.MIS Report Table'!F$6) -> 35842.56 | G12: =SUMIFS(IF(ISEVEN('07.DRW'!$K$4),INDEX(Table1[],,10),INDEX(Table1[],,11)), Table1[[Customer name]:[Customer name]], '02.MIS Report Table'!$A12, Table1[[Payment Method]:[Payment Method]], "Online", Table1[[Product]:[Product]], '02.MIS Report Table'!G$6) -> 42988.52 | H12: =SUMIFS(IF(ISEVEN('07.DRW'!$K$4),INDEX(Table1[],,10),INDEX(Table1[],,11)), Table1[[Customer name]:[Customer name]], '02.MIS Report Table'!$A12, Table1[[Payment Method]:[Payment Method]], "Online", Table1[[Product]:[Product]], '02.MIS Report Table'!H$6) -> 0 | I12: =SUMIFS(IF(ISEVEN('07.DRW'!$K$4),INDEX(Table1[],,10),INDEX(Table1[],,11)), Table1[[Customer name]:[Customer name]], '02.MIS Report Table'!$A12, Table1[[Payment Method]:[Payment Method]], "Online", Table1[[Product]:[Product]], '02.MIS Report Table'!I$6) -> 0 | J12: =SUMIFS(IF(ISEVEN('07.DRW'!$K$4),INDEX(Table1[],,10),INDEX(Table1[],,11)), Table1[[Customer name]:[Customer name]], '02.MIS Report Table'!$A12, Table1[[Payment Method]:[Payment Method]], "Cash", Table1[[Product]:[Product]], '02.MIS Report Table'!B$6) -> 65452.8 | K12: =SUMIFS(IF(ISEVEN('07.DRW'!$K$4),INDEX(Table1[],,10),INDEX(Table1[],,11)), Table1[[Customer name]:[Customer name]], '02.MIS Report Table'!$A12, Table1[[Payment Method]:[Payment Method]], "Cash", Table1[[Product]:[Product]], '02.MIS Report Table'!C$6) -> 19951.68 | L12: =SUMIFS(IF(ISEVEN('07.DRW'!$K$4),INDEX(Table1[],,10),INDEX(Table1[],,11)), Table1[[Customer name]:[Customer name]], '02.MIS Report Table'!$A12, Table1[[Payment Method]:[Payment Method]], "Cash", Table1[[Product]:[Product]], '02.MIS Report Table'!D$6) -> 0 | M12: =SUMIFS(IF(ISEVEN('07.DRW'!$K$4),INDEX(Table1[],,10),INDEX(Table1[],,11)), Table1[[Customer name]:[Customer name]], '02.MIS Report Table'!$A12, Table1[[Payment Method]:[Payment Method]], "Cash", Table1[[Product]:[Product]], '02.MIS Report Table'!E$6) -> 17991 | N12: =SUMIFS(IF(ISEVEN('07.DRW'!$K$4),INDEX(Table1[],,10),INDEX(Table1[],,11)), Table1[[Customer name]:[Customer name]], '02.MIS Report Table'!$A12, Table1[[Payment Method]:[Payment Method]], "Cash", Table1[[Product]:[Product]], '02.MIS Report Table'!F$6) -> 4420.08 | O12: =SUMIFS(IF(ISEVEN('07.DRW'!$K$4),INDEX(Table1[],,10),INDEX(Table1[],,11)), Table1[[Customer name]:[Customer name]], '02.MIS Report Table'!$A12, Table1[[Payment Method]:[Payment Method]], "Cash", Table1[[Product]:[Product]], '02.MIS Report Table'!G$6) -> 0 | P12: =SUMIFS(IF(ISEVEN('07.DRW'!$K$4),INDEX(Table1[],,10),INDEX(Table1[],,11)), Table1[[Customer name]:[Customer name]], '02.MIS Report Table'!$A12, Table1[[Payment Method]:[Payment Method]], "Cash", Table1[[Product]:[Product]], '02.MIS Report Table'!H$6) -> 0 | Q12: =SUMIFS(IF(ISEVEN('07.DRW'!$K$4),INDEX(Table1[],,10),INDEX(Table1[],,11)), Table1[[Customer name]:[Customer name]], '02.MIS Report Table'!$A12, Table1[[Payment Method]:[Payment Method]], "Cash", Table1[[Product]:[Product]], '02.MIS Report Table'!I$6) -> 43898.56 | R12: =SUM(B12:Q12) -> 118788.12
A13: Rahul | B13: =SUMIFS(IF(ISEVEN('07.DRW'!$K$4),INDEX(Table1[],,10),INDEX(Table1[],,11)), Table1[[Customer name]:[Customer name]], '02.MIS Report Table'!$A13, Table1[[Payment Method]:[Payment Method]], "Online", Table1[[Product]:[Product]], '02.MIS Report Table'!B$6) -> 12882.66 | C13: =SUMIFS(IF(ISEVEN('07.DRW'!$K$4),INDEX(Table1[],,10),INDEX(Table1[],,11)), Table1[[Customer name]:[Customer name]], '02.MIS Report Table'!$A13, Table1[[Payment Method]:[Payment Method]], "Online", Table1[[Product]:[Product]], '02.MIS Report Table'!C$6) -> 158461.84 | D13: =SUMIFS(IF(ISEVEN('07.DRW'!$K$4),INDEX(Table1[],,10),INDEX(Table1[],,11)), Table1[[Customer name]:[Customer name]], '02.MIS Report Table'!$A13, Table1[[Payment Method]:[Payment Method]], "Online", Table1[[Product]:[Product]], '02.MIS Report Table'!D$6) -> 28338.3 | E13: =SUMIFS(IF(ISEVEN('07.DRW'!$K$4),INDEX(Table1[],,10),INDEX(Table1[],,11)), Table1[[Customer name]:[Customer name]], '02.MIS Report Table'!$A13, Table1[[Payment Method]:[Payment Method]], "Online", Table1[[Product]:[Product]], '02.MIS Report Table'!E$6) -> 53662.6 | F13: =SUMIFS(IF(ISEVEN('07.DRW'!$K$4),INDEX(Table1[],,10),INDEX(Table1[],,11)), Table1[[Customer name]:[Customer name]], '02.MIS Report Table'!$A13, Table1[[Payment Method]:[Payment Method]], "Online", Table1[[Product]:[Product]], '02.MIS Report Table'!F$6) -> 24453.44 | G13: =SUMIFS(IF(ISEVEN('07.DRW'!$K$4),INDEX(Table1[],,10),INDEX(Table1[],,11)), Table1[[Customer name]:[Customer name]], '02.MIS Report Table'!$A13, Table1[[Payment Method]:[Payment Method]], "Online", Table1[[Product]:[Product]], '02.MIS Report Table'!G$6) -> 16921.92 | H13: =SUMIFS(IF(ISEVEN('07.DRW'!$K$4),INDEX(Table1[],,10),INDEX(Table1[],,11)), Table1[[Customer name]:[Customer name]], '02.MIS Report Table'!$A13, Table1[[Payment Method]:[Payment Method]], "Online", Table1[[Product]:[Product]], '02.MIS Report Table'!H$6) -> 22594.07 | I13: =SUMIFS(IF(ISEVEN('07.DRW'!$K$4),INDEX(Table1[],,10),INDEX(Table1[],,11)), Table1[[Customer name]:[Customer name]], '02.MIS Report Table'!$A13, Table1[[Payment Method]:[Payment Method]], "Online", Table1[[Product]:[Product]], '02.MIS Report Table'!I$6) -> 17298.6 | J13: =SUMIFS(IF(ISEVEN('07.DRW'!$K$4),INDEX(Table1[],,10),INDEX(Table1[],,11)), Table1[[Customer name]:[Customer name]], '02.MIS Report Table'!$A13, Table1[[Payment Method]:[Payment Method]], "Cash", Table1[[Product]:[Product]], '02.MIS Report Table'!B$6) -> 61923.34 | K13: =SUMIFS(IF(ISEVEN('07.DRW'!$K$4),INDEX(Table1[],,10),INDEX(Table1[],,11)), Table1[[Customer name]:[Customer name]], '02.MIS Report Table'!$A13, Table1[[Payment Method]:[Payment Method]], "Cash", Table1[[Product]:[Product]], '02.MIS Report Table'!C$6) -> 45139.36 | L13: =SUMIFS(IF(ISEVEN('07.DRW'!$K$4),INDEX(Table1[],,10),INDEX(Table1[],,11)), Table1[[Customer name]:[Customer name]], '02.MIS Report Table'!$A13, Table1[[Payment Method]:[Payment Method]], "Cash", Table1[[Product]:[Product]], '02.MIS Report Table'!D$6) -> 43792.56 | M13: =SUMIFS(IF(ISEVEN('07.DRW'!$K$4),INDEX(Table1[],,10),INDEX(Table1[],,11)), Table1[[Customer name]:[Customer name]], '02.MIS Report Table'!$A13, Table1[[Payment Method]:[Payment Method]], "Cash", Table1[[Product]:[Product]], '02.MIS Report Table'!E$6) -> 68628.78 | N13: =SUMIFS(IF(ISEVEN('07.DRW'!$K$4),INDEX(Table1[],,10),INDEX(Table1[],,11)), Table1[[Customer name]:[Customer name]], '02.MIS Report Table'!$A13, Table1[[Payment Method]:[Payment Method]], "Cash", Table1[[Product]:[Product]], '02.MIS Report Table'!F$6) -> 41369.66 | O13: =SUMIFS(IF(ISEVEN('07.DRW'!$K$4),INDEX(Table1[],,10),INDEX(Table1[],,11)), Table1[[Customer name]:[Customer name]], '02.MIS Report Table'!$A13, Table1[[Payment Method]:[Payment Method]], "Cash", Table1[[Product]:[Product]], '02.MIS Report Table'!G$6) -> 59989.85 | P13: =SUMIFS(IF(ISEVEN('07.DRW'!$K$4),INDEX(Table1[],,10),INDEX(Table1[],,11)), Table1[[Customer name]:[Customer name]], '02.MIS Report Table'!$A13, Table1[[Payment Method]:[Payment Method]], "Cash", Table1[[Product]:[Product]], '02.MIS Report Table'!H$6) -> 15200 | Q13: =SUMIFS(IF(ISEVEN('07.DRW'!$K$4),INDEX(Table1[],,10),INDEX(Table1[],,11)), Table1[[Customer name]:[Customer name]], '02.MIS Report Table'!$A13, Table1[[Payment Method]:[Payment Method]], "Cash", Table1[[Product]:[Product]], '02.MIS Report Table'!I$6) -> 20838.36 | R13: =SUM(B13:Q13) -> 691495.34
A14: Shivam | B14: =SUMIFS(IF(ISEVEN('07.DRW'!$K$4),INDEX(Table1[],,10),INDEX(Table1[],,11)), Table1[[Customer name]:[Customer name]], '02.MIS Report Table'!$A14, Table1[[Payment Method]:[Payment Method]], "Online", Table1[[Product]:[Product]], '02.MIS Report Table'!B$6) -> 41775.6 | C14: =SUMIFS(IF(ISEVEN('07.DRW'!$K$4),INDEX(Table1[],,10),INDEX(Table1[],,11)), Table1[[Customer name]:[Customer name]], '02.MIS Report Table'!$A14, Table1[[Payment Method]:[Payment Method]], "Online", Table1[[Product]:[Product]], '02.MIS Report Table'!C$6) -> 40856.4 | D14: =SUMIFS(IF(ISEVEN('07.DRW'!$K$4),INDEX(Table1[],,10),INDEX(Table1[],,11)), Table1[[Customer name]:[Customer name]], '02.MIS Report Table'!$A14, Table1[[Payment Method]:[Payment Method]], "Online", Table1[[Product]:[Product]], '02.MIS Report Table'!D$6) -> 37059.12 | E14: =SUMIFS(IF(ISEVEN('07.DRW'!$K$4),INDEX(Table1[],,10),INDEX(Table1[],,11)), Table1[[Customer name]:[Customer name]], '02.MIS Report Table'!$A14, Table1[[Payment Method]:[Payment Method]], "Online", Table1[[Product]:[Product]], '02.MIS Report Table'!E$6) -> 0 | F14: =SUMIFS(IF(ISEVEN('07.DRW'!$K$4),INDEX(Table1[],,10),INDEX(Table1[],,11)), Table1[[Customer name]:[Customer name]], '02.MIS Report Table'!$A14, Table1[[Payment Method]:[Payment Method]], "Online", Table1[[Product]:[Product]], '02.MIS Report Table'!F$6) -> 34743.6 | G14: =SUMIFS(IF(ISEVEN('07.DRW'!$K$4),INDEX(Table1[],,10),INDEX(Table1[],,11)), Table1[[Customer name]:[Customer name]], '02.MIS Report Table'!$A14, Table1[[Payment Method]:[Payment Method]], "Online", Table1[[Product]:[Product]], '02.MIS Report Table'!G$6) -> 63330.22 | H14: =SUMIFS(IF(ISEVEN('07.DRW'!$K$4),INDEX(Table1[],,10),INDEX(Table1[],,11)), Table1[[Customer name]:[Customer name]], '02.MIS Report Table'!$A14, Table1[[Payment Method]:[Payment Method]], "Online", Table1[[Product]:[Product]], '02.MIS Report Table'!H$6) -> 75013.1 | I14: =SUMIFS(IF(ISEVEN('07.DRW'!$K$4),INDEX(Table1[],,10),INDEX(Table1[],,11)), Table1[[Customer name]:[Customer name]], '02.MIS Report Table'!$A14, Table1[[Payment Method]:[Payment Method]], "Online", Table1[[Product]:[Product]], '02.MIS Report Table'!I$6) -> 141693.16 | J14: =SUMIFS(IF(ISEVEN('07.DRW'!$K$4),INDEX(Table1[],,10),INDEX(Table1[],,11)), Table1[[Customer name]:[Customer name]], '02.MIS Report Table'!$A14, Table1[[Payment Method]:[Payment Method]], "Cash", Table1[[Product]:[Product]], '02.MIS Report Table'!B$6) -> 0 | K14: =SUMIFS(IF(ISEVEN('07.DRW'!$K$4),INDEX(Table1[],,10),INDEX(Table1[],,11)), Table1[[Customer name]:[Customer name]], '02.MIS Report Table'!$A14, Table1[[Payment Method]:[Payment Method]], "Cash", Table1[[Product]:[Product]], '02.MIS Report Table'!C$6) -> 87674.85 | L14: =SUMIFS(IF(ISEVEN('07.DRW'!$K$4),INDEX(Table1[],,10),INDEX(Table1[],,11)), Table1[[Customer name]:[Customer name]], '02.MIS Report Table'!$A14, Table1[[Payment Method]:[Payment Method]], "Cash", Table1[[Product]:[Product]], '02.MIS Report Table'!D$6) -> 7242 | M14: =SUMIFS(IF(ISEVEN('07.DRW'!$K$4),INDEX(Table1[],,10),INDEX(Table1[],,11)), Table1[[Customer name]:[Customer name]], '02.MIS Report Table'!$A14, Table1[[Payment Method]:[Payment Method]], "Cash", Table1[[Product]:[Product]], '02.MIS Report Table'!E$6) -> 29282.5 | N14: =SUMIFS(IF(ISEVEN('07.DRW'!$K$4),INDEX(Table1[],,10),INDEX(Table1[],,11)), Table1[[Customer name]:[Customer name]], '02.MIS Report Table'!$A14, Table1[[Payment Method]:[Payment Method]], "Cash", Table1[[Product]:[Product]], '02.MIS Report Table'!F$6) -> 75707.28 | O14: =SUMIFS(IF(ISEVEN('07.DRW'!$K$4),INDEX(Table1[],,10),INDEX(Table1[],,11)), Table1[[Customer name]:[Customer name]], '02.MIS Report Table'!$A14, Table1[[Payment Method]:[Payment Method]], "Cash", Table1[[Product]:[Product]], '02.MIS Report Table'!G$6) -> 36925.32 | P14: =SUMIFS(IF(ISEVEN('07.DRW'!$K$4),INDEX(Table1[],,10),INDEX(Table1[],,11)), Table1[[Customer name]:[Customer name]], '02.MIS Report Table'!$A14, Table1[[Payment Method]:[Payment Method]], "Cash", Table1[[Product]:[Product]], '02.MIS Report Table'!H$6) -> 55295.46 | Q14: =SUMIFS(IF(ISEVEN('07.DRW'!$K$4),INDEX(Table1[],,10),INDEX(Table1[],,11)), Table1[[Customer name]:[Customer name]], '02.MIS Report Table'!$A14, Table1[[Payment Method]:[Payment Method]], "Cash", Table1[[Product]:[Product]], '02.MIS Report Table'!I$6) -> 11021.76 | R14: =SUM(B14:Q14) -> 737620.37
A15: Pooja | B15: =SUMIFS(IF(ISEVEN('07.DRW'!$K$4),INDEX(Table1[],,10),INDEX(Table1[],,11)), Table1[[Customer name]:[Customer name]], '02.MIS Report Table'!$A15, Table1[[Payment Method]:[Payment Method]], "Online", Table1[[Product]:[Product]], '02.MIS Report Table'!B$6) -> 24816 | C15: =SUMIFS(IF(ISEVEN('07.DRW'!$K$4),INDEX(Table1[],,10),INDEX(Table1[],,11)), Table1[[Customer name]:[Customer name]], '02.MIS Report Table'!$A15, Table1[[Payment Method]:[Payment Method]], "Online", Table1[[Product]:[Product]], '02.MIS Report Table'!C$6) -> 8816.22 | D15: =SUMIFS(IF(ISEVEN('07.DRW'!$K$4),INDEX(Table1[],,10),INDEX(Table1[],,11)), Table1[[Customer name]:[Customer name]], '02.MIS Report Table'!$A15, Table1[[Payment Method]:[Payment Method]], "Online", Table1[[Product]:[Product]], '02.MIS Report Table'!D$6) -> 50726.56 | E15: =SUMIFS(IF(ISEVEN('07.DRW'!$K$4),INDEX(Table1[],,10),INDEX(Table1[],,11)), Table1[[Customer name]:[Customer name]], '02.MIS Report Table'!$A15, Table1[[Payment Method]:[Payment Method]], "Online", Table1[[Product]:[Product]], '02.MIS Report Table'!E$6) -> 42223.43 | F15: =SUMIFS(IF(ISEVEN('07.DRW'!$K$4),INDEX(Table1[],,10),INDEX(Table1[],,11)), Table1[[Customer name]:[Customer name]], '02.MIS Report Table'!$A15, Table1[[Payment Method]:[Payment Method]], "Online", Table1[[Product]:[Product]], '02.MIS Report Table'!F$6) -> 25167.33 | G15: =SUMIFS(IF(ISEVEN('07.DRW'!$K$4),INDEX(Table1[],,10),INDEX(Table1[],,11)), Table1[[Customer name]:[Customer name]], '02.MIS Report Table'!$A15, Table1[[Payment Method]:[Payment Method]], "Online", Table1[[Product]:[Product]], '02.MIS Report Table'!G$6) -> 29157.72 | H15: =SUMIFS(IF(ISEVEN('07.DRW'!$K$4),INDEX(Table1[],,10),INDEX(Table1[],,11)), Table1[[Customer name]:[Customer name]], '02.MIS Report Table'!$A15, Table1[[Payment Method]:[Payment Method]], "Online", Table1[[Product]:[Product]], '02.MIS Report Table'!H$6) -> 13886.52 | I15: =SUMIFS(IF(ISEVEN('07.DRW'!$K$4),INDEX(Table1[],,10),INDEX(Table1[],,11)), Table1[[Customer name]:[Customer name]], '02.MIS Report Table'!$A15, Table1[[Payment Method]:[Payment Method]], "Online", Table1[[Product]:[Product]], '02.MIS Report Table'!I$6) -> 48716.27 | J15: =SUMIFS(IF(ISEVEN('07.DRW'!$K$4),INDEX(Table1[],,10),INDEX(Table1[],,11)), Table1[[Customer name]:[Customer name]], '02.MIS Report Table'!$A15, Table1[[Payment Method]:[Payment Method]], "Cash", Table1[[Product]:[Product]], '02.MIS Report Table'!B$6) -> 0 | K15: =SUMIFS(IF(ISEVEN('07.DRW'!$K$4),INDEX(Table1[],,10),INDEX(Table1[],,11)), Table1[[Customer name]:[Customer name]], '02.MIS Report Table'!$A15, Table1[[Payment Method]:[Payment Method]], "Cash", Table1[[Product]:[Product]], '02.MIS Report Table'!C$6) -> 37027.2 | L15: =SUMIFS(IF(ISEVEN('07.DRW'!$K$4),INDEX(Table1[],,10),INDEX(Table1[],,11)), Table1[[Customer name]:[Customer name]], '02.MIS Report Table'!$A15, Table1[[Payment Method]:[Payment Method]], "Cash", Table1[[Product]:[Product]], '02.MIS Report Table'!D$6) -> 23950.62 | M15: =SUMIFS(IF(ISEVEN('07.DRW'!$K$4),INDEX(Table1[],,10),INDEX(Table1[],,11)), Table1[[Customer name]:[Customer name]], '02.MIS Report Table'!$A15, Table1[[Payment Method]:[Payment Method]], "Cash", Table1[[Product]:[Product]], '02.MIS Report Table'!E$6) -> 28551.75 | N15: =SUMIFS(IF(ISEVEN('07.DRW'!$K$4),INDEX(Table1[],,10),INDEX(Table1[],,11)), Table1[[Customer name]:[Customer name]], '02.MIS Report Table'!$A15, Table1[[Payment Method]:[Payment Method]], "Cash", Table1[[Product]:[Product]], '02.MIS Report Table'!F$6) -> 24453.44 | O15: =SUMIFS(IF(ISEVEN('07.DRW'!$K$4),INDEX(Table1[],,10),INDEX(Table1[],,11)), Table1[[Customer name]:[Customer name]], '02.MIS Report Table'!$A15, Table1[[Payment Method]:[Payment Method]], "Cash", Table1[[Product]:[Product]], '02.MIS Report Table'!G$6) -> 57698.52 | P15: =SUMIFS(IF(ISEVEN('07.DRW'!$K$4),INDEX(Table1[],,10),INDEX(Table1[],,11)), Table1[[Customer name]:[Customer name]], '02.MIS Report Table'!$A15, Table1[[Payment Method]:[Payment Method]], "Cash", Table1[[Product]:[Product]], '02.MIS Report Table'!H$6) -> 69422.88 | Q15: =SUMIFS(IF(ISEVEN('07.DRW'!$K$4),INDEX(Table1[],,10),INDEX(Table1[],,11)), Table1[[Customer name]:[Customer name]], '02.MIS Report Table'!$A15, Table1[[Payment Method]:[Payment Method]], "Cash", Table1[[Product]:[Product]], '02.MIS Report Table'!I$6) -> 0 | R15: =SUM(B15:Q15) -> 484614.46
A16: Priya Gupta | B16: =SUMIFS(IF(ISEVEN('07.DRW'!$K$4),INDEX(Table1[],,10),INDEX(Table1[],,11)), Table1[[Customer name]:[Customer name]], '02.MIS Report Table'!$A16, Table1[[Payment Method]:[Payment Method]], "Online", Table1[[Product]:[Product]], '02.MIS Report Table'!B$6) -> 87732.23 | C16: =SUMIFS(IF(ISEVEN('07.DRW'!$K$4),INDEX(Table1[],,10),INDEX(Table1[],,11)), Table1[[Customer name]:[Customer name]], '02.MIS Report Table'!$A16, Table1[[Payment Method]:[Payment Method]], "Online", Table1[[Product]:[Product]], '02.MIS Report Table'!C$6) -> 0 | D16: =SUMIFS(IF(ISEVEN('07.DRW'!$K$4),INDEX(Table1[],,10),INDEX(Table1[],,11)), Table1[[Customer name]:[Customer name]], '02.MIS Report Table'!$A16, Table1[[Payment Method]:[Payment Method]], "Online", Table1[[Product]:[Product]], '02.MIS Report Table'!D$6) -> 65225.8 | E16: =SUMIFS(IF(ISEVEN('07.DRW'!$K$4),INDEX(Table1[],,10),INDEX(Table1[],,11)), Table1[[Customer name]:[Customer name]], '02.MIS Report Table'!$A16, Table1[[Payment Method]:[Payment Method]], "Online", Table1[[Product]:[Product]], '02.MIS Report Table'!E$6) -> 19211.53 | F16: =SUMIFS(IF(ISEVEN('07.DRW'!$K$4),INDEX(Table1[],,10),INDEX(Table1[],,11)), Table1[[Customer name]:[Customer name]], '02.MIS Report Table'!$A16, Table1[[Payment Method]:[Payment Method]], "Online", Table1[[Product]:[Product]], '02.MIS Report Table'!F$6) -> 66184.64 | G16: =SUMIFS(IF(ISEVEN('07.DRW'!$K$4),INDEX(Table1[],,10),INDEX(Table1[],,11)), Table1[[Customer name]:[Customer name]], '02.MIS Report Table'!$A16, Table1[[Payment Method]:[Payment Method]], "Online", Table1[[Product]:[Product]], '02.MIS Report Table'!G$6) -> 87304.2 | H16: =SUMIFS(IF(ISEVEN('07.DRW'!$K$4),INDEX(Table1[],,10),INDEX(Table1[],,11)), Table1[[Customer name]:[Customer name]], '02.MIS Report Table'!$A16, Table1[[Payment Method]:[Payment Method]], "Online", Table1[[Product]:[Product]], '02.MIS Report Table'!H$6) -> 2076.84 | I16: =SUMIFS(IF(ISEVEN('07.DRW'!$K$4),INDEX(Table1[],,10),INDEX(Table1[],,11)), Table1[[Customer name]:[Customer name]], '02.MIS Report Table'!$A16, Table1[[Payment Method]:[Payment Method]], "Online", Table1[[Product]:[Product]], '02.MIS Report Table'!I$6) -> 48710.49 | J16: =SUMIFS(IF(ISEVEN('07.DRW'!$K$4),INDEX(Table1[],,10),INDEX(Table1[],,11)), Table1[[Customer name]:[Customer name]], '02.MIS Report Table'!$A16, Table1[[Payment Method]:[Payment Method]], "Cash", Table1[[Product]:[Product]], '02.MIS Report Table'!B$6) -> 22470 | K16: =SUMIFS(IF(ISEVEN('07.DRW'!$K$4),INDEX(Table1[],,10),INDEX(Table1[],,11)), Table1[[Customer name]:[Customer name]], '02.MIS Report Table'!$A16, Table1[[Payment Method]:[Payment Method]], "Cash", Table1[[Product]:[Product]], '02.MIS Report Table'!C$6) -> 21572.6 | L16: =SUMIFS(IF(ISEVEN('07.DRW'!$K$4),INDEX(Table1[],,10),INDEX(Table1[],,11)), Table1[[Customer name]:[Customer name]], '02.MIS Report Table'!$A16, Table1[[Payment Method]:[Payment Method]], "Cash", Table1[[Product]:[Product]], '02.MIS Report Table'!D$6) -> 0 | M16: =SUMIFS(IF(ISEVEN('07.DRW'!$K$4),INDEX(Table1[],,10),INDEX(Table1[],,11)), Table1[[Customer name]:[Customer name]], '02.MIS Report Table'!$A16, Table1[[Payment Method]:[Payment Method]], "Cash", Table1[[Product]:[Product]], '02.MIS Report Table'!E$6) -> 0 | N16: =SUMIFS(IF(ISEVEN('07.DRW'!$K$4),INDEX(Table1[],,10),INDEX(Table1[],,11)), Table1[[Customer name]:[Customer name]], '02.MIS Report Table'!$A16, Table1[[Payment Method]:[Payment Method]], "Cash", Table1[[Product]:[Product]], '02.MIS Report Table'!F$6) -> 113797.68 | O16: =SUMIFS(IF(ISEVEN('07.DRW'!$K$4),INDEX(Table1[],,10),INDEX(Table1[],,11)), Table1[[Customer name]:[Customer name]], '02.MIS Report Table'!$A16, Table1[[Payment Method]:[Payment Method]], "Cash", Table1[[Product]:[Product]], '02.MIS Report Table'!G$6) -> 10754.1 | P16: =SUMIFS(IF(ISEVEN('07.DRW'!$K$4),INDEX(Table1[],,10),INDEX(Table1[],,11)), Table1[[Customer name]:[Customer name]], '02.MIS Report Table'!$A16, Table1[[Payment Method]:[Payment Method]], "Cash", Table1[[Product]:[Product]], '02.MIS Report Table'!H$6) -> 0 | Q16: =SUMIFS(IF(ISEVEN('07.DRW'!$K$4),INDEX(Table1[],,10),INDEX(Table1[],,11)), Table1[[Customer name]:[Customer name]], '02.MIS Report Table'!$A16, Table1[[Payment Method]:[Payment Method]], "Cash", Table1[[Product]:[Product]], '02.MIS Report Table'!I$6) -> 58108.81 | R16: =SUM(B16:Q16) -> 603148.92
A17: Priya | B17: =SUMIFS(IF(ISEVEN('07.DRW'!$K$4),INDEX(Table1[],,10),INDEX(Table1[],,11)), Table1[[Customer name]:[Customer name]], '02.MIS Report Table'!$A17, Table1[[Payment Method]:[Payment Method]], "Online", Table1[[Product]:[Product]], '02.MIS Report Table'!B$6) -> 100613.95 | C17: =SUMIFS(IF(ISEVEN('07.DRW'!$K$4),INDEX(Table1[],,10),INDEX(Table1[],,11)), Table1[[Customer name]:[Customer name]], '02.MIS Report Table'!$A17, Table1[[Payment Method]:[Payment Method]], "Online", Table1[[Product]:[Product]], '02.MIS Report Table'!C$6) -> 19789.77 | D17: =SUMIFS(IF(ISEVEN('07.DRW'!$K$4),INDEX(Table1[],,10),INDEX(Table1[],,11)), Table1[[Customer name]:[Customer name]], '02.MIS Report Table'!$A17, Table1[[Payment Method]:[Payment Method]], "Online", Table1[[Product]:[Product]], '02.MIS Report Table'!D$6) -> 31183.04 | E17: =SUMIFS(IF(ISEVEN('07.DRW'!$K$4),INDEX(Table1[],,10),INDEX(Table1[],,11)), Table1[[Customer name]:[Customer name]], '02.MIS Report Table'!$A17, Table1[[Payment Method]:[Payment Method]], "Online", Table1[[Product]:[Product]], '02.MIS Report Table'!E$6) -> 2046.24 | F17: =SUMIFS(IF(ISEVEN('07.DRW'!$K$4),INDEX(Table1[],,10),INDEX(Table1[],,11)), Table1[[Customer name]:[Customer name]], '02.MIS Report Table'!$A17, Table1[[Payment Method]:[Payment Method]], "Online", Table1[[Product]:[Product]], '02.MIS Report Table'!F$6) -> 60373.1 | G17: =SUMIFS(IF(ISEVEN('07.DRW'!$K$4),INDEX(Table1[],,10),INDEX(Table1[],,11)), Table1[[Customer name]:[Customer name]], '02.MIS Report Table'!$A17, Table1[[Payment Method]:[Payment Method]], "Online", Table1[[Product]:[Product]], '02.MIS Report Table'!G$6) -> 0 | H17: =SUMIFS(IF(ISEVEN('07.DRW'!$K$4),INDEX(Table1[],,10),INDEX(Table1[],,11)), Table1[[Customer name]:[Customer name]], '02.MIS Report Table'!$A17, Table1[[Payment Method]:[Payment Method]], "Online", Table1[[Product]:[Product]], '02.MIS Report Table'!H$6) -> 77419.44 | I17: =SUMIFS(IF(ISEVEN('07.DRW'!$K$4),INDEX(Table1[],,10),INDEX(Table1[],,11)), Table1[[Customer name]:[Customer name]], '02.MIS Report Table'!$A17, Table1[[Payment Method]:[Payment Method]], "Online", Table1[[Product]:[Product]], '02.MIS Report Table'!I$6) -> 3989.52 | J17: =SUMIFS(IF(ISEVEN('07.DRW'!$K$4),INDEX(Table1[],,10),INDEX(Table1[],,11)), Table1[[Customer name]:[Customer name]], '02.MIS Report Table'!$A17, Table1[[Payment Method]:[Payment Method]], "Cash", Table1[[Product]:[Product]], '02.MIS Report Table'!B$6) -> 0 | K17: =SUMIFS(IF(ISEVEN('07.DRW'!$K$4),INDEX(Table1[],,10),INDEX(Table1[],,11)), Table1[[Customer name]:[Customer name]], '02.MIS Report Table'!$A17, Table1[[Payment Method]:[Payment Method]], "Cash", Table1[[Product]:[Product]], '02.MIS Report Table'!C$6) -> 0 | L17: =SUMIFS(IF(ISEVEN('07.DRW'!$K$4),INDEX(Table1[],,10),INDEX(Table1[],,11)), Table1[[Customer name]:[Customer name]], '02.MIS Report Table'!$A17, Table1[[Payment Method]:[Payment Method]], "Cash", Table1[[Product]:[Product]], '02.MIS Report Table'!D$6) -> 2075.64 | M17: =SUMIFS(IF(ISEVEN('07.DRW'!$K$4),INDEX(Table1[],,10),INDEX(Table1[],,11)), Table1[[Customer name]:[Customer name]], '02.MIS Report Table'!$A17, Table1[[Payment Method]:[Payment Method]], "Cash", Table1[[Product]:[Product]], '02.MIS Report Table'!E$6) -> 0 | N17: =SUMIFS(IF(ISEVEN('07.DRW'!$K$4),INDEX(Table1[],,10),INDEX(Table1[],,11)), Table1[[Customer name]:[Customer name]], '02.MIS Report Table'!$A17, Table1[[Payment Method]:[Payment Method]], "Cash", Table1[[Product]:[Product]], '02.MIS Report Table'!F$6) -> 0 | O17: =SUMIFS(IF(ISEVEN('07.DRW'!$K$4),INDEX(Table1[],,10),INDEX(Table1[],,11)), Table1[[Customer name]:[Customer name]], '02.MIS Report Table'!$A17, Table1[[Payment Method]:[Payment Method]], "Cash", Table1[[Product]:[Product]], '02.MIS Report Table'!G$6) -> 23515.84 | P17: =SUMIFS(IF(ISEVEN('07.DRW'!$K$4),INDEX(Table1[],,10),INDEX(Table1[],,11)), Table1[[Customer name]:[Customer name]], '02.MIS Report Table'!$A17, Table1[[Payment Method]:[Payment Method]], "Cash", Table1[[Product]:[Product]], '02.MIS Report Table'!H$6) -> 24192.75 | Q17: =SUMIFS(IF(ISEVEN('07.DRW'!$K$4),INDEX(Table1[],,10),INDEX(Table1[],,11)), Table1[[Customer name]:[Customer name]], '02.MIS Report Table'!$A17, Table1[[Payment Method]:[Payment Method]], "Cash", Table1[[Product]:[Product]], '02.MIS Report Table'!I$6) -> 19723.2 | R17: =SUM(B17:Q17) -> 364922.49
A18: Total | B18: =SUM(B7:B17) -> 408777.2 | C18: =SUM(C7:C17) -> 574591.11 | D18: =SUM(D7:D17) -> 525382.25 | E18: =SUM(E7:E17) -> 304217.32 | F18: =SUM(F7:F17) -> 138896.4 | G18: =SUM(G7:G17) -> 348399.24 | H18: =SUM(H7:H17) -> 327336.28 | I18: =SUM(I7:I17) -> 327682.08 | ... R18: =SUM(R7:R17) -> 5603323.6

Sheet 04.Report
A1: Payment type by Product Revenue Report
A3: Payment Method | B3: Product | C3: Total Buying | D3: Total Sales | E3: Total Profit
A4: Cash | B4: Headphones | C4: 2222663.3 | D4: 2605472 | E4: 353979.65
B5: Keyboard | C5: 1600327.7 | D5: 1716530 | E5: 322670.25
B6: Laptop | C6: 1530606.7 | D6: 1728541 | E6: 197934.3
B7: Monitor | C7: 1365813.8 | D7: 1587981 | E7: 260293.17
B8: Mouse | C8: 2719610.8 | D8: 2520937 | E8: 450743.17
B9: Printer | C9: 2346270 | D9: 2913564 | E9: 393164.2
B10: Tablet | C10: 2371527.5 | D10: 2679963 | E10: 337433.49
B11: Webcam | C11: 2084165.5 | D11: 2727303 | E11: 331823.45
A12: Cash Total | C12: 16240986 | D12: 18480291 | E12: 2648041.7
A13: Online | B13: Headphones | C13: 2547423.8 | D13: 2918683 | E13: 408777.2
